<?xml version="1.0" encoding="UTF-8"?>
<!-- Generated by org.testng.reporters.JUnitReportReporter -->
<testsuite skipped="0" hostname="MIT01524" name="com.paymentgateway.uat.dps.testcases.RegressionSalesDB" tests="4" failures="1" timestamp="11 Sep 2019 07:08:26 GMT" time="823.963" errors="0">
  <testcase name="testPaySingleInvoiceInConsoleAdmin" time="214.328" classname="com.paymentgateway.uat.dps.testcases.RegressionSalesDB">
    <failure type="java.lang.AssertionError" message="expected [The payment of AU$73.60 for invoice 12135033 has been accepted] but found []">
      <![CDATA[java.lang.AssertionError: expected [The payment of AU$73.60 for invoice 12135033 has been accepted] but found []
at org.testng.Assert.fail(Assert.java:96)
at org.testng.Assert.failNotEquals(Assert.java:776)
at org.testng.Assert.assertEqualsImpl(Assert.java:137)
at org.testng.Assert.assertEquals(Assert.java:118)
at org.testng.Assert.assertEquals(Assert.java:453)
at org.testng.Assert.assertEquals(Assert.java:463)
at com.paymentgateway.uat.dps.testcases.RegressionSalesDB.testPaySingleInvoiceInConsoleAdmin(RegressionSalesDB.java:257)
at sun.reflect.NativeMethodAccessorImpl.invoke0(Native Method)
at sun.reflect.NativeMethodAccessorImpl.invoke(Unknown Source)
at sun.reflect.DelegatingMethodAccessorImpl.invoke(Unknown Source)
at java.lang.reflect.Method.invoke(Unknown Source)
at org.testng.internal.MethodInvocationHelper.invokeMethod(MethodInvocationHelper.java:124)
at org.testng.internal.Invoker.invokeMethod(Invoker.java:583)
at org.testng.internal.Invoker.invokeTestMethod(Invoker.java:719)
at org.testng.internal.Invoker.invokeTestMethods(Invoker.java:989)
at org.testng.internal.TestMethodWorker.invokeTestMethods(TestMethodWorker.java:125)
at org.testng.internal.TestMethodWorker.run(TestMethodWorker.java:109)
at org.testng.TestRunner.privateRun(TestRunner.java:648)
at org.testng.TestRunner.run(TestRunner.java:505)
at org.testng.SuiteRunner.runTest(SuiteRunner.java:455)
at org.testng.SuiteRunner.access$000(SuiteRunner.java:40)
at org.testng.SuiteRunner$SuiteWorker.run(SuiteRunner.java:489)
at org.testng.internal.thread.ThreadUtil$1.call(ThreadUtil.java:52)
at java.util.concurrent.FutureTask.run(Unknown Source)
at java.util.concurrent.ThreadPoolExecutor.runWorker(Unknown Source)
at java.util.concurrent.ThreadPoolExecutor$Worker.run(Unknown Source)
at java.lang.Thread.run(Unknown Source)
]]>
    </failure>
  </testcase> <!-- testPaySingleInvoiceInConsoleAdmin -->
  <testcase name="testDomainRegistration2WorkflowInConsoleAdmin" time="222.099" classname="com.paymentgateway.uat.dps.testcases.RegressionSalesDB"/>
  <testcase name="testCreateDomainAndMajorProductOrderInSalesDB" time="168.198" classname="com.paymentgateway.uat.dps.testcases.RegressionSalesDB"/>
  <testcase name="testProductSetup2WorkflowInConsoleAdmin" time="219.338" classname="com.paymentgateway.uat.dps.testcases.RegressionSalesDB"/>
</testsuite> <!-- com.paymentgateway.uat.dps.testcases.RegressionSalesDB -->
